<?xml version="1.0" ?>
<!-- Generated using onshape-to-robot -->
<!-- Onshape document_id: b8b254ae2dc4b877212314ad -->
<robot name="pybullet">
  <!-- Link corpo_center -->
  <link name="corpo_center">
    <inertial>
      <origin xyz="-7.00181e-05 0.000144946 0.0405122" rpy="0 0 0"/>
      <mass value="0.399518"/>
      <inertia ixx="0.00100114" ixy="1.52509e-06" ixz="5.28428e-07" iyy="0.00212406" iyz="-2.19103e-06" izz="0.00199064"/>
    </inertial>
    <!-- Part corpo_center -->
    <visual>
      <origin xyz="-0.00143743 0.000199567 -0.026" rpy="0 -0 0"/>
      <geometry>
        <mesh filename="package://assets/corpo_center.stl"/>
      </geometry>
      <material name="corpo_center_material">
        <color rgba="0.537255 0.854902 0.827451 1"/>
      </material>
    </visual>
  </link>
  <!-- Link coxa_left -->
  <link name="coxa_left">
    <inertial>
      <origin xyz="-0.00925616 0.0105337 -0.0414798" rpy="0 0 0"/>
      <mass value="0.114719"/>
      <inertia ixx="5.39674e-05" ixy="2.7171e-08" ixz="1.52845e-06" iyy="4.85407e-05" iyz="2.07568e-07" izz="4.06893e-05"/>
    </inertial>
    <!-- Part coxa_left -->
    <visual>
      <origin xyz="0.0958607 -0.104994 -0.1085" rpy="-0 -0 0"/>
      <geometry>
        <mesh filename="package://assets/coxa_left.stl"/>
      </geometry>
      <material name="coxa_left_material">
        <color rgba="0.262745 0.282353 0.301961 1"/>
      </material>
    </visual>
    <collision>
      <origin xyz="0.0958607 -0.104994 -0.1085" rpy="-0 -0 0"/>
      <geometry>
        <mesh filename="package://assets/coxa_left.stl"/>
      </geometry>
    </collision>
  </link>
  <!-- Link femur_left -->
  <link name="femur_left">
    <inertial>
      <origin xyz="-0.00643845 0.0446229 0.0220001" rpy="0 0 0"/>
      <mass value="0.0406019"/>
      <inertia ixx="6.83684e-05" ixy="-9.8624e-08" ixz="-3.156e-09" iyy="2.98626e-05" iyz="3.769e-09" izz="4.36701e-05"/>
    </inertial>
    <!-- Part femur_left -->
    <visual>
      <origin xyz="-0.0563378 -0.180581 -0.0838551" rpy="1.57104 1.57069 1.5708"/>
      <geometry>
        <mesh filename="package://assets/femur_left.stl"/>
      </geometry>
      <material name="femur_left_material">
        <color rgba="0.537255 0.854902 0.827451 1"/>
      </material>
    </visual>
    <collision>
      <origin xyz="-0.0563378 -0.180581 -0.0838551" rpy="1.57104 1.57069 1.5708"/>
      <geometry>
        <mesh filename="package://assets/femur_left.stl"/>
      </geometry>
    </collision>
  </link>
  <!-- Link tibia_left -->
  <link name="tibia_left">
    <inertial>
      <origin xyz="0.00462765 0.0291382 0.0219975" rpy="0 0 0"/>
      <mass value="0.0995945"/>
      <inertia ixx="0.00011091" ixy="-8.06656e-06" ixz="1.813e-09" iyy="1.63167e-05" iyz="7.373e-09" izz="0.00011223"/>
    </inertial>
    <!-- Part tibia_left -->
    <visual>
      <origin xyz="-0.0713466 -0.317596 -0.0837714" rpy="-1.52343 1.57063 -1.5708"/>
      <geometry>
        <mesh filename="package://assets/tibia_left.stl"/>
      </geometry>
      <material name="tibia_left_material">
        <color rgba="0.262745 0.282353 0.301961 1"/>
      </material>
    </visual>
    <collision>
      <origin xyz="-0.0713466 -0.317596 -0.0837714" rpy="-1.52343 1.57063 -1.5708"/>
      <geometry>
        <mesh filename="package://assets/tibia_left.stl"/>
      </geometry>
    </collision>
  </link>
  <!-- Joint from femur_left to tibia_left -->
  <joint name="tibia_1" type="revolute">
    <origin xyz="-4.22005e-05 0.09 -0" rpy="0 -0 -0"/>
    <parent link="femur_left"/>
    <child link="tibia_left"/>
    <axis xyz="0 0 1"/>
    <limit effort="10" velocity="10" lower="-3.14159" upper="3.14159"/>
  </joint>
  <!-- Joint from coxa_left to femur_left -->
  <joint name="femur_1" type="revolute">
    <origin xyz="0.0120255 0.0256037 -0.0522" rpy="-0.000110389 -1.5708 0"/>
    <parent link="coxa_left"/>
    <child link="femur_left"/>
    <axis xyz="0 0 1"/>
    <limit effort="10" velocity="10" lower="-1.5708" upper="1.5708"/>
  </joint>
  <!-- Joint from corpo_center to coxa_left -->
  <joint name="coxa_1" type="revolute">
    <origin xyz="0.090389 0.0557355 0.0825" rpy="0 -0 0"/>
    <parent link="corpo_center"/>
    <child link="coxa_left"/>
    <axis xyz="0 0 1"/>
    <limit effort="10" velocity="10" lower="-1.5708" upper="1.5708"/>
  </joint>
  <!-- Link coxa_left_2 -->
  <link name="coxa_left_2">
    <inertial>
      <origin xyz="-0.00925616 0.0105337 -0.0414798" rpy="0 0 0"/>
      <mass value="0.114719"/>
      <inertia ixx="5.39674e-05" ixy="2.7171e-08" ixz="1.52845e-06" iyy="4.85407e-05" iyz="2.07568e-07" izz="4.06893e-05"/>
    </inertial>
    <!-- Part coxa_left_2 -->
    <visual>
      <origin xyz="0.0958607 -0.104994 -0.1085" rpy="0 -0 0"/>
      <geometry>
        <mesh filename="package://assets/coxa_left.stl"/>
      </geometry>
      <material name="coxa_left_2_material">
        <color rgba="0.262745 0.282353 0.301961 1"/>
      </material>
    </visual>
    <collision>
      <origin xyz="0.0958607 -0.104994 -0.1085" rpy="0 -0 0"/>
      <geometry>
        <mesh filename="package://assets/coxa_left.stl"/>
      </geometry>
    </collision>
  </link>
  <!-- Link femur_left_2 -->
  <link name="femur_left_2">
    <inertial>
      <origin xyz="-0.00643845 0.0446229 0.0220001" rpy="0 0 0"/>
      <mass value="0.0406019"/>
      <inertia ixx="6.83684e-05" ixy="-9.8624e-08" ixz="-3.156e-09" iyy="2.98626e-05" iyz="3.769e-09" izz="4.36701e-05"/>
    </inertial>
    <!-- Part femur_left_2 -->
    <visual>
      <origin xyz="-0.0563378 -0.180581 -0.0838551" rpy="1.57104 1.57069 1.5708"/>
      <geometry>
        <mesh filename="package://assets/femur_left.stl"/>
      </geometry>
      <material name="femur_left_2_material">
        <color rgba="0.537255 0.854902 0.827451 1"/>
      </material>
    </visual>
    <collision>
      <origin xyz="-0.0563378 -0.180581 -0.0838551" rpy="1.57104 1.57069 1.5708"/>
      <geometry>
        <mesh filename="package://assets/femur_left.stl"/>
      </geometry>
    </collision>
  </link>
  <!-- Link tibia_left_2 -->
  <link name="tibia_left_2">
    <inertial>
      <origin xyz="0.00462765 0.0291382 0.0219975" rpy="0 0 0"/>
      <mass value="0.0995945"/>
      <inertia ixx="0.00011091" ixy="-8.06656e-06" ixz="1.813e-09" iyy="1.63167e-05" iyz="7.373e-09" izz="0.00011223"/>
    </inertial>
    <!-- Part tibia_left_2 -->
    <visual>
      <origin xyz="-0.0713466 -0.317596 -0.0837714" rpy="-1.52343 1.57063 -1.5708"/>
      <geometry>
        <mesh filename="package://assets/tibia_left.stl"/>
      </geometry>
      <material name="tibia_left_2_material">
        <color rgba="0.262745 0.282353 0.301961 1"/>
      </material>
    </visual>
    <collision>
      <origin xyz="-0.0713466 -0.317596 -0.0837714" rpy="-1.52343 1.57063 -1.5708"/>
      <geometry>
        <mesh filename="package://assets/tibia_left.stl"/>
      </geometry>
    </collision>
  </link>
  <!-- Joint from femur_left_2 to tibia_left_2 -->
  <joint name="tibia_2" type="revolute">
    <origin xyz="-4.22005e-05 0.09 0" rpy="0 -0 -0"/>
    <parent link="femur_left_2"/>
    <child link="tibia_left_2"/>
    <axis xyz="0 0 1"/>
    <limit effort="10" velocity="10" lower="-3.14159" upper="3.14159"/>
  </joint>
  <!-- Joint from coxa_left_2 to femur_left_2 -->
  <joint name="femur_2" type="revolute">
    <origin xyz="0.0120255 0.0256037 -0.0522" rpy="-0.000110389 -1.5708 0"/>
    <parent link="coxa_left_2"/>
    <child link="femur_left_2"/>
    <axis xyz="0 0 1"/>
    <limit effort="10" velocity="10" lower="-1.5708" upper="1.5708"/>
  </joint>
  <!-- Joint from corpo_center to coxa_left_2 -->
  <joint name="coxa_2" type="revolute">
    <origin xyz="-0.00260145 0.065288 0.0825" rpy="0 -0 0"/>
    <parent link="corpo_center"/>
    <child link="coxa_left_2"/>
    <axis xyz="0 0 1"/>
    <limit effort="10" velocity="10" lower="-1.5708" upper="1.5708"/>
  </joint>
  <!-- Link coxa_left_3 -->
  <link name="coxa_left_3">
    <inertial>
      <origin xyz="-0.00925616 0.0105337 -0.0414798" rpy="0 0 0"/>
      <mass value="0.114719"/>
      <inertia ixx="5.39674e-05" ixy="2.7171e-08" ixz="1.52845e-06" iyy="4.85407e-05" iyz="2.07568e-07" izz="4.06893e-05"/>
    </inertial>
    <!-- Part coxa_left_3 -->
    <visual>
      <origin xyz="0.0958607 -0.104994 -0.1085" rpy="0 -0 0"/>
      <geometry>
        <mesh filename="package://assets/coxa_left.stl"/>
      </geometry>
      <material name="coxa_left_3_material">
        <color rgba="0.262745 0.282353 0.301961 1"/>
      </material>
    </visual>
    <collision>
      <origin xyz="0.0958607 -0.104994 -0.1085" rpy="0 -0 0"/>
      <geometry>
        <mesh filename="package://assets/coxa_left.stl"/>
      </geometry>
    </collision>
  </link>
  <!-- Link femur_left_3 -->
  <link name="femur_left_3">
    <inertial>
      <origin xyz="-0.00643845 0.0446229 0.0220001" rpy="0 0 0"/>
      <mass value="0.0406019"/>
      <inertia ixx="6.83684e-05" ixy="-9.8624e-08" ixz="-3.156e-09" iyy="2.98626e-05" iyz="3.769e-09" izz="4.36701e-05"/>
    </inertial>
    <!-- Part femur_left_3 -->
    <visual>
      <origin xyz="-0.0563378 -0.180581 -0.0838551" rpy="1.57104 1.57069 1.5708"/>
      <geometry>
        <mesh filename="package://assets/femur_left.stl"/>
      </geometry>
      <material name="femur_left_3_material">
        <color rgba="0.537255 0.854902 0.827451 1"/>
      </material>
    </visual>
    <collision>
      <origin xyz="-0.0563378 -0.180581 -0.0838551" rpy="1.57104 1.57069 1.5708"/>
      <geometry>
        <mesh filename="package://assets/femur_left.stl"/>
      </geometry>
    </collision>
  </link>
  <!-- Link tibia_left_3 -->
  <link name="tibia_left_3">
    <inertial>
      <origin xyz="0.00462765 0.0291382 0.0219975" rpy="0 0 0"/>
      <mass value="0.0995945"/>
      <inertia ixx="0.00011091" ixy="-8.06656e-06" ixz="1.813e-09" iyy="1.63167e-05" iyz="7.373e-09" izz="0.00011223"/>
    </inertial>
    <!-- Part tibia_left_3 -->
    <visual>
      <origin xyz="-0.0713466 -0.317596 -0.0837714" rpy="-1.52343 1.57063 -1.5708"/>
      <geometry>
        <mesh filename="package://assets/tibia_left.stl"/>
      </geometry>
      <material name="tibia_left_3_material">
        <color rgba="0.262745 0.282353 0.301961 1"/>
      </material>
    </visual>
    <collision>
      <origin xyz="-0.0713466 -0.317596 -0.0837714" rpy="-1.52343 1.57063 -1.5708"/>
      <geometry>
        <mesh filename="package://assets/tibia_left.stl"/>
      </geometry>
    </collision>
  </link>
  <!-- Joint from femur_left_3 to tibia_left_3 -->
  <joint name="tibia_3" type="revolute">
    <origin xyz="-4.22005e-05 0.09 -0" rpy="0 -0 -0"/>
    <parent link="femur_left_3"/>
    <child link="tibia_left_3"/>
    <axis xyz="0 0 1"/>
    <limit effort="10" velocity="10" lower="-3.14159" upper="3.14159"/>
  </joint>
  <!-- Joint from coxa_left_3 to femur_left_3 -->
  <joint name="femur_3" type="revolute">
    <origin xyz="0.0120255 0.0256037 -0.0522" rpy="-0.000110389 -1.5708 0"/>
    <parent link="coxa_left_3"/>
    <child link="femur_left_3"/>
    <axis xyz="0 0 1"/>
    <limit effort="10" velocity="10" lower="-1.5708" upper="1.5708"/>
  </joint>
  <!-- Joint from corpo_center to coxa_left_3 -->
  <joint name="coxa_3" type="revolute">
    <origin xyz="-0.0975281 0.0553256 0.0825" rpy="0 -0 0"/>
    <parent link="corpo_center"/>
    <child link="coxa_left_3"/>
    <axis xyz="0 0 1"/>
    <limit effort="10" velocity="10" lower="-1.5708" upper="1.5708"/>
  </joint>
  <!-- Link coxa_right -->
  <link name="coxa_right">
    <inertial>
      <origin xyz="0.00925616 0.0105337 -0.0414798" rpy="0 0 0"/>
      <mass value="0.114719"/>
      <inertia ixx="5.39674e-05" ixy="-2.7171e-08" ixz="-1.52845e-06" iyy="4.85407e-05" iyz="2.07568e-07" izz="4.06893e-05"/>
    </inertial>
    <!-- Part coxa_right -->
    <visual>
      <origin xyz="-0.0958607 -0.104994 -0.1085" rpy="0 -0 3.14159"/>
      <geometry>
        <mesh filename="package://assets/coxa_right.stl"/>
      </geometry>
      <material name="coxa_right_material">
        <color rgba="0.262745 0.282353 0.301961 1"/>
      </material>
    </visual>
    <collision>
      <origin xyz="-0.0958607 -0.104994 -0.1085" rpy="0 -0 3.14159"/>
      <geometry>
        <mesh filename="package://assets/coxa_right.stl"/>
      </geometry>
    </collision>
  </link>
  <!-- Link femur_right -->
  <link name="femur_right">
    <inertial>
      <origin xyz="-0.00643859 0.0446229 -0.0220012" rpy="0 0 0"/>
      <mass value="0.0406012"/>
      <inertia ixx="6.83682e-05" ixy="-9.8789e-08" ixz="3.106e-09" iyy="2.98625e-05" iyz="-4.509e-09" izz="4.36704e-05"/>
    </inertial>
    <!-- Part femur_right -->
    <visual>
      <origin xyz="-0.0563378 -0.180581 0.0838551" rpy="1.57055 -1.57069 1.5708"/>
      <geometry>
        <mesh filename="package://assets/femur_right.stl"/>
      </geometry>
      <material name="femur_right_material">
        <color rgba="0.537255 0.854902 0.827451 1"/>
      </material>
    </visual>
    <collision>
      <origin xyz="-0.0563378 -0.180581 0.0838551" rpy="1.57055 -1.57069 1.5708"/>
      <geometry>
        <mesh filename="package://assets/femur_right.stl"/>
      </geometry>
    </collision>
  </link>
  <!-- Link tibia_right -->
  <link name="tibia_right">
    <inertial>
      <origin xyz="0.00462869 0.0291366 -0.0219976" rpy="0 0 0"/>
      <mass value="0.0995772"/>
      <inertia ixx="0.000110896" ixy="-8.06647e-06" ixz="-2.004e-09" iyy="1.63119e-05" iyz="-8.214e-09" izz="0.000112212"/>
    </inertial>
    <!-- Part tibia_right -->
    <visual>
      <origin xyz="-0.0713466 -0.317596 0.0837714" rpy="-1.61816 -1.57063 -1.5708"/>
      <geometry>
        <mesh filename="package://assets/tibia_right.stl"/>
      </geometry>
      <material name="tibia_right_material">
        <color rgba="0.262745 0.282353 0.301961 1"/>
      </material>
    </visual>
    <collision>
      <origin xyz="-0.0713466 -0.317596 0.0837714" rpy="-1.61816 -1.57063 -1.5708"/>
      <geometry>
        <mesh filename="package://assets/tibia_right.stl"/>
      </geometry>
    </collision>
  </link>
  <!-- Joint from femur_right to tibia_right -->
  <joint name="tibia_4" type="revolute">
    <origin xyz="-4.22005e-05 0.09 -0" rpy="-0 -0 -0"/>
    <parent link="femur_right"/>
    <child link="tibia_right"/>
    <axis xyz="0 0 1"/>
    <limit effort="10" velocity="10" lower="-3.14159" upper="3.14159"/>
  </joint>
  <!-- Joint from coxa_right to femur_right -->
  <joint name="femur_4" type="revolute">
    <origin xyz="-0.0120255 0.0256037 -0.0522" rpy="0.000110389 -1.5708 0"/>
    <parent link="coxa_right"/>
    <child link="femur_right"/>
    <axis xyz="0 0 1"/>
    <limit effort="10" velocity="10" lower="-1.5708" upper="1.5708"/>
  </joint>
  <!-- Joint from corpo_center to coxa_right -->
  <joint name="coxa_4" type="revolute">
    <origin xyz="0.090332 -0.055261 0.0825" rpy="-0 0 3.14159"/>
    <parent link="corpo_center"/>
    <child link="coxa_right"/>
    <axis xyz="0 0 1"/>
    <limit effort="10" velocity="10" lower="-1.5708" upper="1.5708"/>
  </joint>
  <!-- Link coxa_right_2 -->
  <link name="coxa_right_2">
    <inertial>
      <origin xyz="0.00925616 0.0105337 -0.0414798" rpy="0 0 0"/>
      <mass value="0.114719"/>
      <inertia ixx="5.39674e-05" ixy="-2.7171e-08" ixz="-1.52845e-06" iyy="4.85407e-05" iyz="2.07568e-07" izz="4.06893e-05"/>
    </inertial>
    <!-- Part coxa_right_2 -->
    <visual>
      <origin xyz="-0.0958607 -0.104994 -0.1085" rpy="0 -0 3.14159"/>
      <geometry>
        <mesh filename="package://assets/coxa_right.stl"/>
      </geometry>
      <material name="coxa_right_2_material">
        <color rgba="0.262745 0.282353 0.301961 1"/>
      </material>
    </visual>
    <collision>
      <origin xyz="-0.0958607 -0.104994 -0.1085" rpy="0 -0 3.14159"/>
      <geometry>
        <mesh filename="package://assets/coxa_right.stl"/>
      </geometry>
    </collision>
  </link>
  <!-- Link femur_right_2 -->
  <link name="femur_right_2">
    <inertial>
      <origin xyz="-0.00643859 0.0446229 -0.0220012" rpy="0 0 0"/>
      <mass value="0.0406012"/>
      <inertia ixx="6.83682e-05" ixy="-9.8789e-08" ixz="3.106e-09" iyy="2.98625e-05" iyz="-4.509e-09" izz="4.36704e-05"/>
    </inertial>
    <!-- Part femur_right_2 -->
    <visual>
      <origin xyz="-0.0563378 -0.180581 0.0838551" rpy="1.57055 -1.57069 1.5708"/>
      <geometry>
        <mesh filename="package://assets/femur_right.stl"/>
      </geometry>
      <material name="femur_right_2_material">
        <color rgba="0.537255 0.854902 0.827451 1"/>
      </material>
    </visual>
    <collision>
      <origin xyz="-0.0563378 -0.180581 0.0838551" rpy="1.57055 -1.57069 1.5708"/>
      <geometry>
        <mesh filename="package://assets/femur_right.stl"/>
      </geometry>
    </collision>
  </link>
  <!-- Link tibia_right_2 -->
  <link name="tibia_right_2">
    <inertial>
      <origin xyz="0.00462869 0.0291366 -0.0219976" rpy="0 0 0"/>
      <mass value="0.0995772"/>
      <inertia ixx="0.000110896" ixy="-8.06647e-06" ixz="-2.004e-09" iyy="1.63119e-05" iyz="-8.214e-09" izz="0.000112212"/>
    </inertial>
    <!-- Part tibia_right_2 -->
    <visual>
      <origin xyz="-0.0713466 -0.317596 0.0837714" rpy="-1.61816 -1.57063 -1.5708"/>
      <geometry>
        <mesh filename="package://assets/tibia_right.stl"/>
      </geometry>
      <material name="tibia_right_2_material">
        <color rgba="0.262745 0.282353 0.301961 1"/>
      </material>
    </visual>
    <collision>
      <origin xyz="-0.0713466 -0.317596 0.0837714" rpy="-1.61816 -1.57063 -1.5708"/>
      <geometry>
        <mesh filename="package://assets/tibia_right.stl"/>
      </geometry>
    </collision>
  </link>
  <!-- Joint from femur_right_2 to tibia_right_2 -->
  <joint name="tibia_5" type="revolute">
    <origin xyz="-4.22005e-05 0.09 -0" rpy="-0 0 -0"/>
    <parent link="femur_right_2"/>
    <child link="tibia_right_2"/>
    <axis xyz="0 0 1"/>
    <limit effort="10" velocity="10" lower="-3.14159" upper="3.14159"/>
  </joint>
  <!-- Joint from coxa_right_2 to femur_right_2 -->
  <joint name="femur_5" type="revolute">
    <origin xyz="-0.0120255 0.0256037 -0.0522" rpy="0.000110389 -1.5708 0"/>
    <parent link="coxa_right_2"/>
    <child link="femur_right_2"/>
    <axis xyz="0 0 1"/>
    <limit effort="10" velocity="10" lower="-1.5708" upper="1.5708"/>
  </joint>
  <!-- Joint from corpo_center to coxa_right_2 -->
  <joint name="coxa_5" type="revolute">
    <origin xyz="-0.00265937 -0.064712 0.0825" rpy="0 -0 3.14159"/>
    <parent link="corpo_center"/>
    <child link="coxa_right_2"/>
    <axis xyz="0 0 1"/>
    <limit effort="10" velocity="10" lower="-1.5708" upper="1.5708"/>
  </joint>
  <!-- Link coxa_right_3 -->
  <link name="coxa_right_3">
    <inertial>
      <origin xyz="0.00925616 0.0105337 -0.0414798" rpy="0 0 0"/>
      <mass value="0.114719"/>
      <inertia ixx="5.39674e-05" ixy="-2.7171e-08" ixz="-1.52845e-06" iyy="4.85407e-05" iyz="2.07568e-07" izz="4.06893e-05"/>
    </inertial>
    <!-- Part coxa_right_3 -->
    <visual>
      <origin xyz="-0.0958607 -0.104994 -0.1085" rpy="0 -0 3.14159"/>
      <geometry>
        <mesh filename="package://assets/coxa_right.stl"/>
      </geometry>
      <material name="coxa_right_3_material">
        <color rgba="0.262745 0.282353 0.301961 1"/>
      </material>
    </visual>
    <collision>
      <origin xyz="-0.0958607 -0.104994 -0.1085" rpy="0 -0 3.14159"/>
      <geometry>
        <mesh filename="package://assets/coxa_right.stl"/>
      </geometry>
    </collision>
  </link>
  <!-- Link femur_right_3 -->
  <link name="femur_right_3">
    <inertial>
      <origin xyz="-0.00643859 0.0446229 -0.0220012" rpy="0 0 0"/>
      <mass value="0.0406012"/>
      <inertia ixx="6.83682e-05" ixy="-9.8789e-08" ixz="3.106e-09" iyy="2.98625e-05" iyz="-4.509e-09" izz="4.36704e-05"/>
    </inertial>
    <!-- Part femur_right_3 -->
    <visual>
      <origin xyz="-0.0563378 -0.180581 0.0838551" rpy="1.57055 -1.57069 1.5708"/>
      <geometry>
        <mesh filename="package://assets/femur_right.stl"/>
      </geometry>
      <material name="femur_right_3_material">
        <color rgba="0.537255 0.854902 0.827451 1"/>
      </material>
    </visual>
    <collision>
      <origin xyz="-0.0563378 -0.180581 0.0838551" rpy="1.57055 -1.57069 1.5708"/>
      <geometry>
        <mesh filename="package://assets/femur_right.stl"/>
      </geometry>
    </collision>
  </link>
  <!-- Link tibia_right_3 -->
  <link name="tibia_right_3">
    <inertial>
      <origin xyz="0.00462869 0.0291366 -0.0219976" rpy="0 0 0"/>
      <mass value="0.0995772"/>
      <inertia ixx="0.000110896" ixy="-8.06647e-06" ixz="-2.004e-09" iyy="1.63119e-05" iyz="-8.214e-09" izz="0.000112212"/>
    </inertial>
    <!-- Part tibia_right_3 -->
    <visual>
      <origin xyz="-0.0713466 -0.317596 0.0837714" rpy="-1.61816 -1.57063 -1.5708"/>
      <geometry>
        <mesh filename="package://assets/tibia_right.stl"/>
      </geometry>
      <material name="tibia_right_3_material">
        <color rgba="0.262745 0.282353 0.301961 1"/>
      </material>
    </visual>
    <collision>
      <origin xyz="-0.0713466 -0.317596 0.0837714" rpy="-1.61816 -1.57063 -1.5708"/>
      <geometry>
        <mesh filename="package://assets/tibia_right.stl"/>
      </geometry>
    </collision>
  </link>
  <!-- Joint from femur_right_3 to tibia_right_3 -->
  <joint name="tibia_6" type="revolute">
    <origin xyz="-4.22005e-05 0.09 0" rpy="-0 0 -0"/>
    <parent link="femur_right_3"/>
    <child link="tibia_right_3"/>
    <axis xyz="0 0 1"/>
    <limit effort="10" velocity="10" lower="-3.14159" upper="3.14159"/>
  </joint>
  <!-- Joint from coxa_right_3 to femur_right_3 -->
  <joint name="femur_6" type="revolute">
    <origin xyz="-0.0120255 0.0256037 -0.0522" rpy="0.000110389 -1.5708 0"/>
    <parent link="coxa_right_3"/>
    <child link="femur_right_3"/>
    <axis xyz="0 0 1"/>
    <limit effort="10" velocity="10" lower="-1.5708" upper="1.5708"/>
  </joint>
  <!-- Joint from corpo_center to coxa_right_3 -->
  <joint name="coxa_6" type="revolute">
    <origin xyz="-0.0975677 -0.0546697 0.0825" rpy="0 -0 3.14159"/>
    <parent link="corpo_center"/>
    <child link="coxa_right_3"/>
    <axis xyz="0 0 1"/>
    <limit effort="10" velocity="10" lower="-1.5708" upper="1.5708"/>
  </joint>
</robot>
